02:51:00.791 (791678386)|EXECUTION_STARTED
02:51:00.791 (791694273)|CODE_UNIT_STARTED|[EXTERNAL]|execute_anonymous_apex
02:51:00.791 (792377345)|USER_DEBUG|[3]|DEBUG|Simple log messages
02:51:00.791 (792401485)|USER_DEBUG|[4]|DEBUG|
02:51:01.935 (1935209042)|USER_DEBUG|[67]|INFO|This is an info message
02:51:01.935 (1935558809)|USER_DEBUG|[67]|WARN|This is a warning message
02:51:01.935 (1935812015)|USER_DEBUG|[67]|ERROR|This is an error message
02:51:01.935 (1935846467)|USER_DEBUG|[9]|DEBUG|
02:51:01.935 (1935862137)|USER_DEBUG|[10]|DEBUG|Log messages with a related SObject
02:51:01.935 (1935872814)|USER_DEBUG|[11]|DEBUG|
02:51:01.935 (1936189302)|USER_DEBUG|[67]|INFO|On 0032D00000WOOuxQAH: This is an info message
02:51:01.935 (1936443191)|USER_DEBUG|[67]|WARN|On 0032D00000WOOuxQAH: This is a warning message
02:51:01.935 (1936854864)|USER_DEBUG|[67]|ERROR|On 0032D00000WOOuxQAH: This is an error message
02:51:01.935 (1936905300)|USER_DEBUG|[16]|DEBUG|
02:51:01.935 (1936932495)|USER_DEBUG|[17]|DEBUG|Log of DML Exception with an Id
02:51:01.935 (1936951327)|USER_DEBUG|[18]|DEBUG|
02:51:01.935 (1953554596)|EXCEPTION_THROWN|[21]|System.DmlException: Update failed. First exception on row 0 with id 0032D00000WOOuxQAH; first error: INVALID_CROSS_REFERENCE_KEY, invalid cross reference id: []
02:51:01.935 (1964267890)|USER_DEBUG|[22]|DEBUG|If "System.TypeException: Invalid conversion ... to DateTime" is seen in the logs, this may be due to an attempt to find the class name of an object
02:51:01.935 (1964538318)|EXCEPTION_THROWN|[23]|System.TypeException: Invalid conversion from runtime type System.DmlException to Datetime
02:51:01.935 (1965044400)|USER_DEBUG|[67]|ERROR|System.DmlException on 0032D00000WOOuxQAH: Update failed. First exception on row 0 with id 0032D00000WOOuxQAH; first error: INVALID_CROSS_REFERENCE_KEY, invalid cross reference id: []
02:51:01.935 (1965268393)|USER_DEBUG|[67]|ERROR|System.DmlException.stackTrace: AnonymousBlock: line 21, column 1
02:51:01.935 (1965316407)|USER_DEBUG|[28]|DEBUG|
02:51:01.935 (1965339303)|USER_DEBUG|[29]|DEBUG|Log of DML Exceptionm, handled with Exception with an Id
02:51:01.935 (1965356877)|USER_DEBUG|[30]|DEBUG|
02:51:01.935 (1972980002)|EXCEPTION_THROWN|[33]|System.DmlException: Update failed. First exception on row 0 with id 0032D00000WOOuxQAH; first error: INVALID_CROSS_REFERENCE_KEY, invalid cross reference id: []
02:51:01.935 (1974428727)|USER_DEBUG|[22]|DEBUG|If "System.TypeException: Invalid conversion ... to DateTime" is seen in the logs, this may be due to an attempt to find the class name of an object
02:51:01.935 (1974469663)|EXCEPTION_THROWN|[23]|System.TypeException: Invalid conversion from runtime type System.DmlException to Datetime
02:51:01.935 (1974703407)|USER_DEBUG|[67]|ERROR|System.DmlException on 0032D00000WOOuxQAH: Update failed. First exception on row 0 with id 0032D00000WOOuxQAH; first error: INVALID_CROSS_REFERENCE_KEY, invalid cross reference id: []
02:51:01.935 (1974772660)|USER_DEBUG|[67]|ERROR|System.DmlException.stackTrace: AnonymousBlock: line 33, column 1
02:51:01.935 (1985162537)|USER_DEBUG|[22]|DEBUG|If "System.TypeException: Invalid conversion ... to DateTime" is seen in the logs, this may be due to an attempt to find the class name of an object
02:51:01.935 (1985231110)|EXCEPTION_THROWN|[23]|System.TypeException: Invalid conversion from runtime type System.DmlException to Datetime
02:51:01.935 (1985510402)|USER_DEBUG|[67]|ERROR|System.DmlException: Update failed. First exception on row 0 with id 0032D00000WOOuxQAH; first error: INVALID_CROSS_REFERENCE_KEY, invalid cross reference id: []
02:51:01.935 (1985632539)|USER_DEBUG|[67]|ERROR|System.DmlException.stackTrace: AnonymousBlock: line 33, column 1
02:51:01.935 (1985684026)|USER_DEBUG|[40]|DEBUG|
02:51:01.935 (1985711709)|USER_DEBUG|[41]|DEBUG|Log of DML Exception without an Id
02:51:01.935 (1985728986)|USER_DEBUG|[42]|DEBUG|
02:51:01.935 (2015827389)|CODE_UNIT_STARTED|[EXTERNAL]|DuplicateDetector
02:51:01.935 (2186162000)|CODE_UNIT_FINISHED|DuplicateDetector
02:51:01.935 (2188225501)|EXCEPTION_THROWN|[45]|System.DmlException: Insert failed. First exception on row 0; first error: REQUIRED_FIELD_MISSING, Required fields are missing: [LastName]: [LastName]
02:51:01.935 (2189360275)|USER_DEBUG|[22]|DEBUG|If "System.TypeException: Invalid conversion ... to DateTime" is seen in the logs, this may be due to an attempt to find the class name of an object
02:51:01.935 (2189411859)|EXCEPTION_THROWN|[23]|System.TypeException: Invalid conversion from runtime type System.DmlException to Datetime
02:51:01.935 (2189688138)|USER_DEBUG|[67]|ERROR|System.DmlException: Insert failed. First exception on row 0; first error: REQUIRED_FIELD_MISSING, Required fields are missing: [LastName]: [LastName]
02:51:01.935 (2189792264)|USER_DEBUG|[67]|ERROR|System.DmlException.stackTrace: AnonymousBlock: line 45, column 1
02:51:01.935 (2190405508)|USER_DEBUG|[52]|DEBUG|
02:51:01.935 (2190427591)|USER_DEBUG|[53]|DEBUG|Log of DML Exception as Exception without an Id
02:51:01.935 (2190438543)|USER_DEBUG|[54]|DEBUG|
02:51:01.935 (2192472306)|CODE_UNIT_STARTED|[EXTERNAL]|DuplicateDetector
02:51:01.935 (2209035541)|CODE_UNIT_FINISHED|DuplicateDetector
02:51:01.935 (2210562454)|EXCEPTION_THROWN|[57]|System.DmlException: Insert failed. First exception on row 0; first error: REQUIRED_FIELD_MISSING, Required fields are missing: [LastName]: [LastName]
02:51:01.935 (2211534916)|USER_DEBUG|[22]|DEBUG|If "System.TypeException: Invalid conversion ... to DateTime" is seen in the logs, this may be due to an attempt to find the class name of an object
02:51:01.935 (2211571908)|EXCEPTION_THROWN|[23]|System.TypeException: Invalid conversion from runtime type System.DmlException to Datetime
02:51:01.935 (2211740656)|USER_DEBUG|[67]|ERROR|System.DmlException: Insert failed. First exception on row 0; first error: REQUIRED_FIELD_MISSING, Required fields are missing: [LastName]: [LastName]
02:51:01.935 (2211814622)|USER_DEBUG|[67]|ERROR|System.DmlException.stackTrace: AnonymousBlock: line 57, column 1
02:51:01.935 (2212143632)|USER_DEBUG|[22]|DEBUG|If "System.TypeException: Invalid conversion ... to DateTime" is seen in the logs, this may be due to an attempt to find the class name of an object
02:51:01.935 (2212176697)|EXCEPTION_THROWN|[23]|System.TypeException: Invalid conversion from runtime type System.DmlException to Datetime
02:51:01.935 (2212325013)|USER_DEBUG|[67]|ERROR|System.DmlException: Insert failed. First exception on row 0; first error: REQUIRED_FIELD_MISSING, Required fields are missing: [LastName]: [LastName]
02:51:01.935 (2212413099)|USER_DEBUG|[67]|ERROR|System.DmlException.stackTrace: AnonymousBlock: line 57, column 1
02:51:01.935 (2212462478)|USER_DEBUG|[64]|DEBUG|
02:51:01.935 (2212487261)|USER_DEBUG|[65]|DEBUG|Log of System Exception without an Id
02:51:01.935 (2212506239)|USER_DEBUG|[66]|DEBUG|
02:51:01.935 (2212939746)|USER_DEBUG|[22]|DEBUG|If "System.TypeException: Invalid conversion ... to DateTime" is seen in the logs, this may be due to an attempt to find the class name of an object
02:51:01.935 (2212964227)|EXCEPTION_THROWN|[23]|System.TypeException: Invalid conversion from runtime type System.ListException to Datetime
02:51:01.935 (2213063462)|USER_DEBUG|[67]|ERROR|System.ListException: List index out of bounds: 1
02:51:01.935 (2213127893)|USER_DEBUG|[67]|ERROR|System.ListException.stackTrace: AnonymousBlock: line 69, column 1
02:51:01.935 (2213154598)|USER_DEBUG|[76]|DEBUG|
02:51:01.935 (2213169184)|USER_DEBUG|[77]|DEBUG|Log of System Exception with an Id
02:51:01.935 (2213180086)|USER_DEBUG|[78]|DEBUG|
02:51:01.935 (2213574398)|USER_DEBUG|[22]|DEBUG|If "System.TypeException: Invalid conversion ... to DateTime" is seen in the logs, this may be due to an attempt to find the class name of an object
02:51:01.935 (2213599086)|EXCEPTION_THROWN|[23]|System.TypeException: Invalid conversion from runtime type System.ListException to Datetime
02:51:01.935 (2213728002)|USER_DEBUG|[67]|ERROR|System.ListException on 0032D00000WOOuxQAH: List index out of bounds: 1
02:51:01.935 (2213796224)|USER_DEBUG|[67]|ERROR|System.ListException.stackTrace: AnonymousBlock: line 81, column 1
02:51:01.935 (2213833219)|USER_DEBUG|[88]|DEBUG|
02:51:01.935 (2213854295)|USER_DEBUG|[89]|DEBUG|Log of Ortoo Exception
02:51:01.935 (2213870070)|USER_DEBUG|[90]|DEBUG|
02:51:01.935 (2268644921)|EXCEPTION_THROWN|[118]|ortoo_qra.Exceptions.DeveloperException: This is a developer exception
02:51:01.935 (2268714664)|EXCEPTION_THROWN|[94]|ortoo_qra.Exceptions.DeveloperException: This is a developer exception
02:51:01.935 (2269353565)|USER_DEBUG|[22]|DEBUG|If "System.TypeException: Invalid conversion ... to DateTime" is seen in the logs, this may be due to an attempt to find the class name of an object
02:51:01.935 (2269407229)|EXCEPTION_THROWN|[23]|System.TypeException: Invalid conversion from runtime type ortoo_qra.Exceptions.DeveloperException to Datetime
02:51:01.935 (2269652077)|USER_DEBUG|[67]|ERROR|ortoo_qra.Exceptions.DeveloperException (DEV-12345): This is a developer exception
02:51:01.935 (2270475427)|USER_DEBUG|[67]|ERROR|ortoo_qra.Exceptions.DeveloperException (DEV-12345).context: id = 0032D00000WOOuxQAH @ OrtooExceptionThrower.throwException on Line: 120, Column 1
02:51:01.935 (2270774457)|USER_DEBUG|[67]|ERROR|ortoo_qra.Exceptions.DeveloperException (DEV-12345).context: otherThing = thingvalue @ OrtooExceptionThrower.throwException on Line: 121, Column 1
02:51:01.935 (2271130489)|USER_DEBUG|[67]|ERROR|ortoo_qra.Exceptions.DeveloperException (DEV-12345).messageDetail: LastName => "The last name went wrong" on Contact:{LastName=thingthatwentwrong}
02:51:01.935 (2271211562)|USER_DEBUG|[67]|ERROR|ortoo_qra.Exceptions.DeveloperException (DEV-12345).stackTrace: Class.OrtooExceptionThrower.throwException: line 118, column 1
AnonymousBlock: line 94, column 1
AnonymousBlock: line 94, column 1
02:51:01.935 (2271249740)|USER_DEBUG|[101]|DEBUG|
02:51:01.935 (2271263621)|USER_DEBUG|[102]|DEBUG|Log of Ortoo Exception as Exception
02:51:01.935 (2271274825)|USER_DEBUG|[103]|DEBUG|
02:51:01.935 (2272311191)|EXCEPTION_THROWN|[118]|ortoo_qra.Exceptions.DeveloperException: This is a developer exception
02:51:01.935 (2272333244)|EXCEPTION_THROWN|[107]|ortoo_qra.Exceptions.DeveloperException: This is a developer exception
02:51:01.935 (2272678717)|USER_DEBUG|[22]|DEBUG|If "System.TypeException: Invalid conversion ... to DateTime" is seen in the logs, this may be due to an attempt to find the class name of an object
02:51:01.935 (2272712012)|EXCEPTION_THROWN|[23]|System.TypeException: Invalid conversion from runtime type ortoo_qra.Exceptions.DeveloperException to Datetime
02:51:01.935 (2272818147)|USER_DEBUG|[67]|ERROR|ortoo_qra.Exceptions.DeveloperException (DEV-12345): This is a developer exception
02:51:01.935 (2273056014)|USER_DEBUG|[67]|ERROR|ortoo_qra.Exceptions.DeveloperException (DEV-12345).context: id = 0032D00000WOOuxQAH @ OrtooExceptionThrower.throwException on Line: 120, Column 1
02:51:01.935 (2273270569)|USER_DEBUG|[67]|ERROR|ortoo_qra.Exceptions.DeveloperException (DEV-12345).context: otherThing = thingvalue @ OrtooExceptionThrower.throwException on Line: 121, Column 1
02:51:01.935 (2273401941)|USER_DEBUG|[67]|ERROR|ortoo_qra.Exceptions.DeveloperException (DEV-12345).messageDetail: LastName => "The last name went wrong" on Contact:{LastName=thingthatwentwrong}
02:51:01.935 (2273456114)|USER_DEBUG|[67]|ERROR|ortoo_qra.Exceptions.DeveloperException (DEV-12345).stackTrace: Class.OrtooExceptionThrower.throwException: line 118, column 1
AnonymousBlock: line 107, column 1
AnonymousBlock: line 107, column 1
02:51:01.935 (2273656621)|USER_DEBUG|[22]|DEBUG|If "System.TypeException: Invalid conversion ... to DateTime" is seen in the logs, this may be due to an attempt to find the class name of an object
02:51:01.935 (2273688189)|EXCEPTION_THROWN|[23]|System.TypeException: Invalid conversion from runtime type ortoo_qra.Exceptions.DeveloperException to Datetime
02:51:01.935 (2273777899)|USER_DEBUG|[67]|ERROR|ortoo_qra.Exceptions.DeveloperException: This is a developer exception
02:51:01.935 (2273827394)|USER_DEBUG|[67]|ERROR|ortoo_qra.Exceptions.DeveloperException.stackTrace: Class.OrtooExceptionThrower.throwException: line 118, column 1
AnonymousBlock: line 107, column 1
AnonymousBlock: line 107, column 1